/******************************************************************************
* Copyright 2015-2022 Xilinx, Inc.
* Copyright 2022-2023 Advanced Micro Devices, Inc.
*
* Licensed under the Apache License, Version 2.0 (the "License");
* you may not use this file except in compliance with the License.
* You may obtain a copy of the License at
* 
* http://www.apache.org/licenses/LICENSE-2.0
* 
* Unless required by applicable law or agreed to in writing, software
* distributed under the License is distributed on an "AS IS" BASIS,
* WITHOUT WARRANTIES OR CONDITIONS OF ANY KIND, either express or implied.
* See the License for the specific language governing permissions and
* limitations under the License.
******************************************************************************/

#include "test_framework.h"
#include "mock_classes.h"

// Simulate main function behavior for exception testing
int SimulateMain(int argc, const char* argv[]) {
    try {
        TestableBootGenApp app;
        app.Run(argc, argv);
        return 0;
    }
    catch(std::exception& ex) {
        return 1;
    }
    catch(const char* msg) {
        return 2;
    }
    catch(...) {
        return 3;
    }
}

void test_MainFunction_SuccessfulExecution() {
    const char* argv[] = {"bootgen", "-help"};
    int result = SimulateMain(2, argv);
    
    // Should return 0 for successful execution
    EXPECT_EQ(0, result);
}

void test_MainFunction_CatchStdException() {
    // Test std::exception handling
    try {
        throw std::runtime_error("Test error message");
    } catch(std::exception& ex) {
        std::string message = ex.what();
        EXPECT_TRUE(message.find("Test error message") != std::string::npos);
        EXPECT_STREQ("Test error message", ex.what());
    }
}

void test_MainFunction_CatchCharPointerException() {
    // Test const char* exception handling
    try {
        throw "Internal assertion failed";
    } catch(const char* msg) {
        std::string message = msg;
        EXPECT_TRUE(message.find("Internal assertion failed") != std::string::npos);
        EXPECT_STREQ("Internal assertion failed", msg);
    }
}

void test_MainFunction_CatchUnknownException() {
    // Test unknown exception handling
    bool caught_unknown = false;
    try {
        throw 42; // Some unknown exception type
    } catch(...) {
        caught_unknown = true;
    }
    
    EXPECT_TRUE(caught_unknown);
}

void test_MainFunction_ExceptionReturnCodes() {
    // Test that different exception types return different codes
    
    // Test with a function that throws std::exception
    auto throw_std_exception = []() -> int {
        try {
            throw std::runtime_error("test");
        } catch(std::exception& ex) {
            return 1;
        } catch(const char* msg) {
            return 2;
        } catch(...) {
            return 3;
        }
    };
    
    EXPECT_EQ(1, throw_std_exception());
    
    // Test with a function that throws const char*
    auto throw_char_exception = []() -> int {
        try {
            throw "test error";
        } catch(std::exception& ex) {
            return 1;
        } catch(const char* msg) {
            return 2;
        } catch(...) {
            return 3;
        }
    };
    
    EXPECT_EQ(2, throw_char_exception());
    
    // Test with a function that throws unknown type
    auto throw_unknown_exception = []() -> int {
        try {
            throw 123;
        } catch(std::exception& ex) {
            return 1;
        } catch(const char* msg) {
            return 2;
        } catch(...) {
            return 3;
        }
    };
    
    EXPECT_EQ(3, throw_unknown_exception());
}

void test_ExceptionSafety_NestedTryCatch() {
    bool inner_caught = false;
    bool outer_caught = false;
    
    try {
        try {
            throw std::runtime_error("Inner exception");
        } catch(std::exception& ex) {
            inner_caught = true;
            // Re-throw to test outer catch
            throw;
        }
    } catch(std::exception& ex) {
        outer_caught = true;
        EXPECT_STREQ("Inner exception", ex.what());
    }
    
    EXPECT_TRUE(inner_caught);
    EXPECT_TRUE(outer_caught);
}

void test_ExceptionSafety_MultipleExceptionTypes() {
    std::vector<int> results;
    
    // Test multiple exception types in sequence
    for (int i = 0; i < 3; ++i) {
        try {
            if (i == 0) {
                throw std::runtime_error("std exception");
            } else if (i == 1) {
                throw "char exception";
            } else {
                throw i;
            }
        } catch(std::exception& ex) {
            results.push_back(1);
        } catch(const char* msg) {
            results.push_back(2);
        } catch(...) {
            results.push_back(3);
        }
    }
    
    EXPECT_EQ(3, results.size());
    EXPECT_EQ(1, results[0]);
    EXPECT_EQ(2, results[1]);
    EXPECT_EQ(3, results[2]);
}

void test_ExceptionSafety_ResourceCleanup() {
    // Test that resources are cleaned up properly during exceptions
    bool cleanup_called = false;
    
    struct RAIIResource {
        bool& cleanup_ref;
        RAIIResource(bool& ref) : cleanup_ref(ref) {}
        ~RAIIResource() { cleanup_ref = true; }
    };
    
    try {
        RAIIResource resource(cleanup_called);
        throw std::runtime_error("Test exception");
    } catch(std::exception& ex) {
        // Exception caught, resource should be cleaned up
    }
    
    EXPECT_TRUE(cleanup_called);
}

int main() {
    std::cout << "Running Exception Handling Tests..." << std::endl;
    std::cout << "===================================" << std::endl;

    RUN_TEST(test_MainFunction_SuccessfulExecution);
    RUN_TEST(test_MainFunction_CatchStdException);
    RUN_TEST(test_MainFunction_CatchCharPointerException);
    RUN_TEST(test_MainFunction_CatchUnknownException);
    RUN_TEST(test_MainFunction_ExceptionReturnCodes);
    RUN_TEST(test_ExceptionSafety_NestedTryCatch);
    RUN_TEST(test_ExceptionSafety_MultipleExceptionTypes);
    RUN_TEST(test_ExceptionSafety_ResourceCleanup);

    print_test_summary();
    generate_test_report("exception_handling_report.txt");
    
    return get_exit_code();
}
